Workbook

Sheet PROFIL CALON KADES
A1: NO URUT | B1: NAMA | C1: VISI DAN MISI | D1: SUARA | E1: PERSEN
A2: 1 | B2: Belum diteteapkan | C2: - | D2: =SUM('INPUT SUARA'!B2:B3) -> 0 | E2: =IF(SUM($D$2:$D$6)=0, 0, D2/SUM($D$2:$D$6)) -> 0
A3: 2 | B3: Belum diteteapkan | C3: - | D3: =SUM('INPUT SUARA'!B3:B4) -> 0 | E3: =IF(SUM($D$2:$D$6)=0, 0, D3/SUM($D$2:$D$6)) -> 0
A4: 3 | B4: Belum diteteapkan | C4: - | D4: =SUM('INPUT SUARA'!B4:B5) -> 0 | E4: =IF(SUM($D$2:$D$6)=0, 0, D4/SUM($D$2:$D$6)) -> 0
A5: 4 | B5: Belum diteteapkan | C5: - | D5: =SUM('INPUT SUARA'!B5:B6) -> 0 | E5: =IF(SUM($D$2:$D$6)=0, 0, D5/SUM($D$2:$D$6)) -> 0
A6: 5 | B6: Belum diteteapkan | C6: - | D6: =SUM('INPUT SUARA'!B6:B7) -> 0 | E6: =IF(SUM($D$2:$D$6)=0, 0, D6/SUM($D$2:$D$6)) -> 0

Sheet DPT AWAL KPU
A2: DP-ID | B2: NKK | C2: NIK | D2: NAMA | E2: TEMPAT LAHIR | F2: TANGGAL LAHIR | G2: USIA | H2: STS KAWIN | I2: L/P | J2: DUSUN/ALAMAT | K2: RT KTP
A3: DP-0002 | B3: 1203063101170001 | C3: 1471046704830042 | D3: CAHAYA PANGARIBUAN | E3: PADANG SIDEMPUAN | F3: 30433 | G3: 43 | H3: S | I3: P | J3: PAYO LEBAR SINGKUT DUSUN DUA | K3: 12
A4: DP-0003 | B4: 1203063101170001 | C4: 1471040506750001 | D4: JHONNY PURBA | E4: SIDIKALANG | F4: 27550 | G4: 51 | H4: S | I4: L | J4: PAYO LEBAR SINGKUT DUSUN DUA | K4: 12
A5: DP-0004 | B5: 1209082503151005 | C5: 1209080911871001 | D5: FUDANI LUBIS | E5: DESA GAJAH | F5: 32090 | G5: 38 | H5: S | I5: L | J5: SUKA JADI | K5: 11
A6: DP-0005 | B6: 1209082503151005 | C6: 1209084107941001 | D6: IDA MARIA BR. HUTAHAEAN | E6: SELAT PANJANG | F6: 34516 | G6: 32 | H6: S | I6: P | J6: SUKA JADI | K6: 11
A7: DP-0006 | B7: 1302110307200002 | C7: 1302113112920001 | D7: DONI ARIANTO | E7: BEKASI | F7: 33969 | G7: 33 | H7: S | I7: L | J7: DUSUN VI REMBEJAYA | K7: 29
A8: DP-0007 | B8: 1302110307200002 | C8: 1503096512920001 | D8: EMI DEVITA | E8: PAYO LEBAR | F8: 33963 | G8: 33 | H8: S | I8: P | J8: DUSUN VI REMBEJAYA | K8: 29
A9: DP-0008 | B9: 1502102205180002 | C9: 1503096212940002 | D9: LUSIA SINTIA LARASATI | E9: PAYO LEBAR | F9: 34690 | G9: 31 | H9: S | I9: P | J9: DUSUN I KARYA MAKMUR | K9: 9
A10: DP-0009 | B10: 1502102205180002 | C10: 1502102112910001 | D10: S. HENDRI HARDIYANTO | E10: BUKIT BERINGIN | F10: 33593 | G10: 34 | H10: S | I10: L | J10: DUSUN I KARYA MAKMUR | K10: 9
A11: DP-0010 | B11: 1503011711150004 | C11: 1502031012760001 | D11: MARKUM. BT | E11: NGAWI | F11: 28095 | G11: 49 | H11: S | I11: L | J11: DUSUN IV RAMBE JAYA | K11: 35
A12: DP-0011 | B12: 1503011711150004 | C12: 1502034505930001 | D12: TITI LESTARI | E12: BADAK TEKURUNG | F12: 34094 | G12: 33 | H12: S | I12: P | J12: DUSUN IV RAMBE JAYA | K12: 35
A13: DP-0012 | B13: 1503022804220003 | C13: 1503020112900003 | D13: ABDULLAH ROZI | E13: SUNGAI BEDURI | F13: 33208 | G13: 35 | H13: S | I13: L | J13: DUSUN IV RAMBE JAYA | K13: 34
A14: DP-0013 | B14: 1503022804220003 | C14: 1503094412970001 | D14: KASTINI | E14: PAYO LEBAR | F14: 35768 | G14: 28 | H14: S | I14: P | J14: DUSUN IV RAMBE JAYA | K14: 34
... A4074: DP-4072 | B4074: 8172042911100003 | C4074: 8172044405730001 | D4074: SITI QOIRIYAH | E4074: SEMARANG | F4074: 26788 | G4074: 53 | H4074: S | I4074: P | J4074: PAYO LEBAR | K4074: 10

Sheet DPS (SEMENTARA)
A1: DP-ID | B1: NKK | C1: NIK | D1: NAMA | E1: TEMPAT LAHIR | F1: TANGGAL LAHIR | G1: USIA | H1: STS KAWIN | I1: L/P | J1: DUSUN/ALAMAT | K1: RT DOMISILI | L1: KODE COKLIT | M1: KETERANGAN COKLIT | N1: TPS
A2: DP-0002 | B2: 1203063101170001 | C2: 1471046704830042 | D2: CAHAYA PANGARIBUAN | E2: PADANG SIDEMPUAN | F2: 30433 | G2: =DATEDIF(F2, DATE(2026, 10, 29), "Y") -> 43 | H2: S | I2: P | J2: PAYO LEBAR SINGKUT DUSUN DUA | K2: 12 | L2: 5 | N2: -
A3: DP-0003 | B3: 1203063101170001 | C3: 1471040506750001 | D3: JHONNY PURBA | E3: SIDIKALANG | F3: 27550 | G3: =DATEDIF(F3, DATE(2026, 10, 29), "Y") -> 51 | H3: S | I3: L | J3: PAYO LEBAR SINGKUT DUSUN DUA | K3: 12 | L3: 5 | N3: -
A4: DP-0004 | B4: 1209082503151005 | C4: 1209080911871001 | D4: FUDANI LUBIS | E4: DESA GAJAH | F4: 32090 | G4: =DATEDIF(F4, DATE(2026, 10, 29), "Y") -> 38 | H4: S | I4: L | J4: SUKA JADI | K4: 11 | L4: 5 | N4: -
A5: DP-0005 | B5: 1209082503151005 | C5: 1209084107941001 | D5: IDA MARIA BR. HUTAHAEAN | E5: SELAT PANJANG | F5: 34516 | G5: =DATEDIF(F5, DATE(2026, 10, 29), "Y") -> 32 | H5: S | I5: P | J5: SUKA JADI | K5: 11 | L5: 5 | N5: -
A6: DP-0006 | B6: 1302110307200002 | C6: 1302113112920001 | D6: DONI ARIANTO | E6: BEKASI | F6: 33969 | G6: =DATEDIF(F6, DATE(2026, 10, 29), "Y") -> 33 | H6: S | I6: L | J6: DUSUN VI REMBEJAYA | K6: 29 | L6: 0 | N6: -
A7: DP-0007 | B7: 1302110307200002 | C7: 1503096512920001 | D7: EMI DEVITA | E7: PAYO LEBAR | F7: 33963 | G7: =DATEDIF(F7, DATE(2026, 10, 29), "Y") -> 33 | H7: S | I7: P | J7: DUSUN VI REMBEJAYA | K7: 29 | L7: 0 | N7: -
A8: DP-0008 | B8: 1502102205180002 | C8: 1503096212940002 | D8: LUSIA SINTIA LARASATI | E8: PAYO LEBAR | F8: 34690 | G8: =DATEDIF(F8, DATE(2026, 10, 29), "Y") -> 31 | H8: S | I8: P | J8: DUSUN I KARYA MAKMUR | K8: 9 | L8: 5 | N8: -
A9: DP-0009 | B9: 1502102205180002 | C9: 1502102112910001 | D9: S. HENDRI HARDIYANTO | E9: BUKIT BERINGIN | F9: 33593 | G9: =DATEDIF(F9, DATE(2026, 10, 29), "Y") -> 34 | H9: S | I9: L | J9: DUSUN I KARYA MAKMUR | K9: 9 | L9: 5 | N9: -
A10: DP-0010 | B10: 1503011711150004 | C10: 1502031012760001 | D10: MARKUM. BT | E10: NGAWI | F10: 28095 | G10: =DATEDIF(F10, DATE(2026, 10, 29), "Y") -> 49 | H10: S | I10: L | J10: DUSUN IV RAMBE JAYA | K10: 35 | L10: 0 | N10: -
A11: DP-0011 | B11: 1503011711150004 | C11: 1502034505930001 | D11: TITI LESTARI | E11: BADAK TEKURUNG | F11: 34094 | G11: =DATEDIF(F11, DATE(2026, 10, 29), "Y") -> 33 | H11: S | I11: P | J11: DUSUN IV RAMBE JAYA | K11: 35 | L11: 0 | N11: -
A12: DP-0012 | B12: 1503022804220003 | C12: 1503020112900003 | D12: ABDULLAH ROZI | E12: SUNGAI BEDURI | F12: 33208 | G12: =DATEDIF(F12, DATE(2026, 10, 29), "Y") -> 35 | H12: S | I12: L | J12: DUSUN IV RAMBE JAYA | K12: 34 | L12: 0 | N12: -
A13: DP-0013 | B13: 1503022804220003 | C13: 1503094412970001 | D13: KASTINI | E13: PAYO LEBAR | F13: 35768 | G13: =DATEDIF(F13, DATE(2026, 10, 29), "Y") -> 28 | H13: S | I13: P | J13: DUSUN IV RAMBE JAYA | K13: 34 | L13: 0 | N13: -
... A29: DP-0029 | B29: 1503032312190010 | C29: 1503056007960002 | D29: NUURUSSA'ADAH AL MUSTAQIMA | E29: PEMATANG KOLIM | F29: 35266 | G29: =DATEDIF(F29, DATE(2026, 10, 29), "Y") -> 30 | H29: S | I29: P | J29: DUSUN I KARYA AGUNG | K29: 22 | L29: 0 | N29: -
A30: DP-0030 | B30: 1503032511190002 | C30: 1503031409930004 | D30: DIDIK SAPUTRA | E30: BERNAI | F30: 34287 | G30: =DATEDIF(F30, DATE(2026, 10, 29), "Y") -> 32 | H30: S | I30: L | J30: DUSUN RAMBE JAYA | K30: 30 | L30: 5 | M30: Lokasi Belum Jelas | N30: -
A31: DP-0031 | B31: 1503032511190002 | C31: 1503090809070002 | D31: SEPTIAN DWI CAHYO | E31: SAROLANGUN | F31: 39333 | G31: =DATEDIF(F31, DATE(2026, 10, 29), "Y") -> 19 | H31: B | I31: L | J31: DUSUN RAMBE JAYA | K31: 30 | L31: 0 | N31: -
A32: DP-0032 | B32: 1503032511190002 | C32: 1503095007790001 | D32: TITIK SUWANTI | E32: SINGKUT | F32: 29046 | G32: =DATEDIF(F32, DATE(2026, 10, 29), "Y") -> 47 | H32: S | I32: P | J32: DUSUN RAMBE JAYA | K32: 30 | L32: 0 | N32: -
A33: DP-0033 | B33: 1503032703140001 | C33: 1503036405890004 | D33: ASNI | E33: BERNAI | F33: 32652 | G33: =DATEDIF(F33, DATE(2026, 10, 29), "Y") -> 37 | H33: S | I33: P | J33: DUSUN II | K33: 11 | L33: 0 | N33: -
A34: DP-0034 | B34: 1503032703140001 | C34: 1503091208890001 | D34: YUDIANTO | E34: PAYO LEBAR | F34: 32732 | G34: =DATEDIF(F34, DATE(2026, 10, 29), "Y") -> 37 | H34: S | I34: L | J34: DUSUN II | K34: 11 | L34: 0 | N34: -
A35: DP-0035 | B35: 1503033108180001 | C35: 1503035511750001 | D35: ALIA MUSNI | E35: PADANG | F35: 27713 | G35: =DATEDIF(F35, DATE(2026, 10, 29), "Y") -> 50 | H35: S | I35: P | J35: DUSUN IV RAMBE JAYA | K35: 29 | L35: 0 | N35: -
A36: DP-0036 | B36: 1503033108180001 | C36: 1503032703780001 | D36: DEDE CANIAGO | E36: CURUP | F36: 28576 | G36: =DATEDIF(F36, DATE(2026, 10, 29), "Y") -> 48 | H36: S | I36: L | J36: DUSUN IV RAMBE JAYA | K36: 29 | L36: 0 | N36: -
A37: DP-0037 | B37: 1503033108180001 | C37: 1503032705810001 | D37: FIRMAN | E37: JAMBI | F37: 29733 | G37: =DATEDIF(F37, DATE(2026, 10, 29), "Y") -> 45 | H37: B | I37: L | J37: DUSUN IV RAMBE JAYA | K37: 29 | L37: 0 | N37: -
A38: DP-0038 | B38: 1503033108180001 | C38: 1503035703010001 | D38: MIFTA NULJANNAH | E38: SAROLANGUN | F38: 37201 | G38: =DATEDIF(F38, DATE(2026, 10, 29), "Y") -> 24 | H38: B | I38: P | J38: DUSUN IV RAMBE JAYA | K38: 29 | L38: 0 | N38: -
A39: DP-0039 | B39: 1503033108180001 | C39: 1503031208040001 | D39: SYIFA NAWAL HANAN | E39: SAROLANGUN | F39: 38211 | G39: =DATEDIF(F39, DATE(2026, 10, 29), "Y") -> 22 | H39: B | I39: P | J39: DUSUN IV RAMBE JAYA | K39: 29 | L39: 0 | N39: -
A40: DP-0040 | B40: 1503033108200014 | C40: 1503032102930001 | D40: FERY APRIYANTO | E40: SINGKUT | F40: 34021 | G40: =DATEDIF(F40, DATE(2026, 10, 29), "Y") -> 33 | H40: S | I40: L | J40: DUSUN KARYA AGUNG | K40: 4 | L40: 5 | N40: -
A41: DP-0041 | B41: 1503033108200014 | C41: 1503095505950003 | D41: PUTRI AZIZAH | E41: LAMPUNG | F41: 34865 | G41: =DATEDIF(F41, DATE(2026, 10, 29), "Y") -> 31 | H41: S | I41: P | J41: DUSUN KARYA AGUNG | K41: 4 | L41: 5 | N41: -
A42: DP-0042 | B42: 1503050102120022 | C42: 1503054807070001 | D42: MARISA HERLINDA | E42: REJO MULYO | F42: 39056 | G42: =DATEDIF(F42, DATE(2026, 10, 29), "Y") -> 19 | H42: B | I42: P | J42: DUSUN I KARYA AGUNG | K42: 10 | L42: 0 | N42: -
... A51: DP-0051 | B51: 1503050401130008 | C51: 1503050904790003 | D51: MARKONI | E51: PENEGAH | F51: 28954 | G51: =DATEDIF(F51, DATE(2026, 10, 29), "Y") -> 47 | H51: S | I51: L | J51: DESA PAYO LEBAR | K51: 25 | L51: 0 | N51: -
A52: DP-0052 | B52: 1503050401130008 | C52: 1604125503880001 | D52: YESY ANGGRIANI | E52: TANJUNG RAYA | F52: 32217 | G52: =DATEDIF(F52, DATE(2026, 10, 29), "Y") -> 38 | H52: S | I52: P | J52: DESA PAYO LEBAR | K52: 25 | L52: u | N52: -
A53: DP-0053 | B53: 1503050502200003 | C53: 1503095907930001 | D53: AJI SARINDAH | E53: PAYO LEBAR | F53: 34038 | G53: =DATEDIF(F53, DATE(2026, 10, 29), "Y") -> 33 | H53: S | I53: P | J53: DUSUN I KARYA AGUNG | K53: 9 | L53: 0 | N53: -
A54: DP-0054 | B54: 1503050502200003 | C54: 1503050803900006 | D54: HERI SETIAWAN | E54: SAROLANGUN | F54: 32940 | G54: =DATEDIF(F54, DATE(2026, 10, 29), "Y") -> 36 | H54: S | I54: L | J54: DUSUN I KARYA AGUNG | K54: 9 | L54: 0 | N54: -
A55: DP-0055 | B55: 1503092812230005 | C55: 1503094511910004 | D55: RISA NOVI YANA YANTI | E55: SARKO | F55: 33547 | G55: =DATEDIF(F55, DATE(2026, 10, 29), "Y") -> 34 | H55: P | I55: P | J55: JLN. MANGKU BUMI | K55: 10 | L55: 0 | N55: -
A56: DP-0056 | B56: 1503050703230001 | C56: 1503056211070001 | D56: ANANDA SELVIA | E56: TSM PEMATANG KOLIM | F56: 39043 | G56: =DATEDIF(F56, DATE(2026, 10, 29), "Y") -> 19 | H56: B | I56: P | J56: DUSUN II SUKA JADI | K56: 16 | L56: 0 | N56: -
A57: DP-0057 | B57: 1503050703230001 | C57: 1503056611790004 | D57: IDA SUSANTI | E57: SAROLANGUN | F57: 29185 | G57: =DATEDIF(F57, DATE(2026, 10, 29), "Y") -> 46 | H57: S | I57: P | J57: DUSUN II SUKA JADI | K57: 16 | L57: 0 | N57: -
A58: DP-0058 | B58: 1503050703230001 | C58: 1503051103730003 | D58: SANTO | E58: MADIUN | F58: 26734 | G58: =DATEDIF(F58, DATE(2026, 10, 29), "Y") -> 53 | H58: S | I58: L | J58: DUSUN II SUKA JADI | K58: 16 | L58: 0 | N58: -
A59: DP-0059 | B59: 1503050707150001 | C59: 1503052308920005 | D59: DENA MASRIADI | E59: PEMATANG KULIM | F59: 33839 | G59: =DATEDIF(F59, DATE(2026, 10, 29), "Y") -> 34 | H59: S | I59: L | J59: DUSUN II SUKAJADI | K59: 11 | L59: 0 | N59: -
A60: DP-0060 | B60: 1503050707150001 | C60: 1503096008960003 | D60: NOVIANA MAYA SARI | E60: SINGKUT | F60: 35297 | G60: =DATEDIF(F60, DATE(2026, 10, 29), "Y") -> 30 | H60: S | I60: P | J60: DUSUN II SUKAJADI | K60: 11 | L60: 0 | N60: -
A61: DP-0061 | B61: 1503050812150002 | C61: 1503051108700001 | D61: MUHAMMAD ALPAN | E61: LUMAJANG | F61: 25791 | G61: =DATEDIF(F61, DATE(2026, 10, 29), "Y") -> 56 | H61: S | I61: L | J61: DUSUN II SUKAJADI | K61: 13 | L61: 8 | M61: KK Pematang Kolim | N61: -
A62: DP-0062 | B62: 1503050812150002 | C62: 1503056201770002 | D62: SUPARIDAH | E62: LAMPUNG | F62: 28298 | G62: =DATEDIF(F62, DATE(2026, 10, 29), "Y") -> 49 | H62: S | I62: P | J62: DUSUN II SUKAJADI | K62: 13 | L62: 8 | M62: KK Pematang Kolim | N62: -
A63: DP-0063 | B63: 1503050909200005 | C63: 1503052708940001 | D63: MUJIANTO | E63: LAMPUNG | F63: 34573 | G63: =DATEDIF(F63, DATE(2026, 10, 29), "Y") -> 32 | H63: S | I63: L | J63: DUSUN IV RAMBE JAYA | K63: 35 | L63: 0 | N63: -
...

Sheet DPTAM (TAMBAHAN)
A1: DP-ID | B1: NKK | C1: NIK | D1: NAMA | E1: TEMPAT LAHIR | F1: TANGGAL LAHIR | G1: USIA | H1: STS KAWIN | I1: L/P | J1: DUSUN/ALAMAT | K1: RT DOMISILI | L1: KODE COKLIT | M1: KETERANGAN COKLIT | N1: TPS

Sheet DPT (TETAP)
A1: DP-ID | B1: NKK | C1: NIK | D1: NAMA | E1: TEMPAT LAHIR | F1: TANGGAL LAHIR | G1: USIA | H1: STS KAWIN | I1: L/P | J1: DUSUN/ALAMAT | K1: RT DOMISILI | L1: KODE COKLIT | M1: KETERANGAN COKLIT | N1: TPS

Sheet PPS (PANITIA DESA)
A1: NAMA | B1: JABATAN
A2: BADRUN, S.E., M.Pd | B2: KETUA
A3: Ir. SAIKUN SUGONDO | B3: WAKIL KETUA
A4: ADI SETIAWAN, S.Pd | B4: SEKRETARIS
A5: KRIS SUDARTO | B5: ANGGOTA
A6: EKO PURNA IRAWAN | B6: SEKRETARIAT

Sheet PENGAWAS BPD
A1: NAMA | B1: JABATAN
A2: HALIMUN SIRI, S.Pd.I | B2: KETUA
A3: SUKARDI | B3: WAKIL KETUA
A4: TEDDY KARTIWAN | B4: SEKRETARIS
A5: - | B5: ANGGOTA
A6: - | B6: ANGGOTA
A7: - | B7: ANGGOTA
A8: - | B8: ANGGOTA
A9: - | B9: ANGGOTA
A10: - | B10: ANGGOTA

Sheet KPPS TPS 01
A1: NAMA | B1: JABATAN
A2: - | B2: KETUA
A3: - | B3: ANGGOTA
A4: - | B4: ANGGOTA
A5: - | B5: ANGGOTA
A6: - | B6: ANGGOTA
A7: - | B7: ANGGOTA
A8: - | B8: ANGGOTA
A9: - | B9: LINMAS
A10: - | B10: LINMAS

Sheet KPPS TPS 02
A1: NAMA | B1: JABATAN
A2: - | B2: KETUA
A3: - | B3: ANGGOTA
A4: - | B4: ANGGOTA
A5: - | B5: ANGGOTA
A6: - | B6: ANGGOTA
A7: - | B7: ANGGOTA
A8: - | B8: ANGGOTA
A9: - | B9: LINMAS
A10: - | B10: LINMAS

Sheet INPUT SUARA
A1: TPS | B1: NOMOR URUT 01 | C1: NOMOR URUT 02 | D1: NOMOR URUT 03 | E1: NOMOR URUT 04 | F1: NOMOR URUT 05 | G1: SUARA SAH | H1: SUARA TIDAK SAH | I1: TOTAL SUARA MASUK | J1: STATUS
A2: 01 | B2: 0 | C2: 0 | D2: 0 | E2: 0 | F2: 0 | G2: =SUM(B2:F2) -> 0 | H2: 0 | I2: =G2+H2 -> 0 | J2: =IF(I2>0, "Selesai", "Belum Selesai") -> Belum Selesai
A3: 02 | B3: 0 | C3: 0 | D3: 0 | E3: 0 | F3: 0 | G3: =SUM(B3:F3) -> 0 | H3: 0 | I3: =G3+H3 -> 0 | J3: =IF(I3>0, "Selesai", "Belum Selesai") -> Belum Selesai
